Workbook

Sheet Leyenda
A1: PVC · Calculadora CTCx v2.1.1 · Ponderación de Valor de Cosecha Colombia · modelo de plataforma
A3: Método: PVC-D2 v2.1.1 · Datos: PVC-D1 v2.1.1 · Edición precargada: PVC-F4-2026 (corte 4-sep-2026, reedición v2.1 9-sep-2026 con series oficiales). Comparador: precio efectivo de cooperativa (PEC) + prima objetivo.
A4: Celdas en AZUL = entradas que se editan cada edición. Celdas en NEGRO = fórmulas (no editar). Fondo AMARILLO = parámetros de decisión de CTCx (sólo cambian entre franjas, con acta).
A5: Flujo: 1) Entradas → 2) Scorecard → 3) Calculo (automático) → 4) Escalera → 5) Contrato (oferta a un productor) → 6) Disparador (vigilancia diaria del FNC) → 7) Calendario → 8) Pila_de_precios (precio al comprador FCA/CIP/DDP en US$/kg; TODOS sus costos son ESTIMADOS, fondo naranja, hasta tener cotizaciones). Datos_mensual y BackProof contienen la serie reconstruida y el back-proof v2.0 (valores del motor pvc_model_v2.py).
A6: Unidades: COP por carga de 125 kg pergamino seco FR 94; C en US¢/lb; TRM en COP/USD; US$/lb sobre 205,2 lb de excelso por carga.
A7: Toda cifra debe ser rastreable a PVC-D1 (fuente, fecha). Archivar una copia con el código de edición al publicar. El motor pvc_model_v2.py reproduce esta hoja con código.

Sheet Entradas
A1: Entradas de la edición
A3: Parámetro | B3: Valor | C3: Unidad | D3: Fuente / nota (PVC-D1, D2)
A4: Código de edición | B4: PVC-F4-2026 | D4: Ficha D3 §1
A5: Fecha de corte | B5: 2026-09-04 | D5: Edición de transición (D3 §1); calendario regular desde F1-2027
A6: FNC mes 1 (abril 2026) – precio interno FR 94 promedio | B6: 2229900 | C6: COP/carga | D6: Promedio mensual oficial FNC (D1 §4, Excel Precios, área y producción ago-2026)
A7: FNC mes 2 (mayo 2026) | B7: 2229129 | C7: COP/carga | D7: Promedio mensual oficial FNC
A8: FNC mes 3 (junio 2026) | B8: 2086866.7 | C8: COP/carga | D8: Promedio mensual oficial FNC
A9: FNC mes 4 (julio 2026) | B9: 2244839 | C9: COP/carga | D9: Promedio mensual oficial FNC
A10: FNC mes 5 (agosto 2026) | B10: 2263548.4 | C10: COP/carga | D10: Promedio mensual oficial FNC
A11: Promedio FNC 30 días al corte | B11: 2252419 | C11: COP/carga | D11: Serie diaria oficial FNC, 31 días calendario 5-ago a 4-sep-2026 (hábiles: 2,248,913)
A12: Máximo FNC últimos 90 días | B12: 2520000 | C12: COP/carga | D12: Serie diaria oficial, 06-jul-2026 (prueba de §4.5)
A13: Máximo FNC últimos 30 días | B13: 2395000 | C13: COP/carga | D13: Serie diaria oficial, 18-ago-2026 (prueba de §4.5)
A14: Promedio FNC últimos 180 días | B14: 2213674 | C14: COP/carga | D14: Serie diaria oficial, 8-mar a 4-sep-2026 (prueba de §4.5)
A15: Precio FNC FR 94 el día de corte | B15: 2080000 | C15: COP/carga | D15: FNC 4-sep-2026
A16: Sobreprecio incondicional de cooperativa PEC-ADD | B16: 60000 | C16: COP/carga | D16: D1 §5: tableros Alto Occidente / Norte de Caldas / Aguadas + reliquidación; rango 40.000–90.000; PIC/MECIC = 0
A17: Prima objetivo p sobre el PEC de 30 días | B17: 0.08 | C17: % | D17: D2 §4.4 (decisión CTCx)
... A20: TRM spot al corte | B20: 3141.36 | C20: COP/USD | D20: Banco de la República / Superfinanciera, datos.gov.co (32sa-8pi3), vigencia 4-sep-2026
A21: Coeficiente k (traslado FNC) | B21: 0.967 | D21: Calibrado con FNC 11-ago-2026
A22: Libras de excelso por carga FR 94 | B22: 205.2 | C22: lb | D22: 93,09 kg × 2,20462
A23: Libras de pergamino por carga | B23: 275.58 | C23: lb | D23: 125 kg × 2,20462
A24: Costo medio FEPCafé (último publicado) | B24: 1550805 | C24: COP/carga | D24: FEPCafé Reporte mensual feb-2026
A25: Escalamiento del costo al corte | B25: 0.06 | C25: % | D25: Índice 69/25/6 (D2 §5); +6% feb→ago 2026 (estimado)
A26: Margen de dignidad | B26: 0.5 | C26: % | D26: Decisión CTCx (D2 §5): piso = costo × 1,50
A27: Desembolso de caja como fracción del costo | B27: 0.73 | C27: % | D27: D2 §5.2 (referencia declarada)
A28: Peso mirada atrás (L) | B28: 0.6 | C28: % | D28: D2 §4.3
A29: Peso proyección (P) | B29: 0.4 | C29: % | D29: D2 §4.3
A30: Tope de impulso | B30: 0.05 | C30: % | D30: D2 §4.2
A31: Paso del modificador por punto | B31: 0.075 | C31: % | D31: D2 §6
A32: Collar del modificador | B32: 0.15 | C32: % | D32: D2 §6
A33: PVC de la franja anterior (0 si no existe) | B33: 0 | C33: COP/carga | D33: D2 §7.1
... A52: Subsidio de catación por defecto | B52: 0.3 | C52: % | D52: D2 §11.4 (el productor paga el resto por adelantado)

Sheet Scorecard
A1: Scorecard de factores paralelos (D2 §6)
A3: Factor | B3: Peso | C3: Puntaje (−2…+2) | D3: Contribución | E3: Justificación / dato (D1)
A4: Sub-índice O&D cafetero | B4: 0.3 | C4: 1 | D4: =B4*C4 | E4: Stocks certificados 223.911 sacos (mínimo desde 1999); cola de graduación baja; curva en backwardation; balance global excedentario compensado por caída de producción colombiana.
A5: Clima / ENSO | B5: 0.2 | C5: 1 | D5: =B5*C5 | E5: NOAA: >90% de probabilidad de El Niño muy fuerte OND 2026; amenaza declarada, impacto no materializado.
A6: BRL/USD | B6: 0.15 | C6: 0 | D6: =B6*C6 | E6: Real en rango 5,13–5,20; sin señal direccional.
A7: COP/USD (TRM) | B7: 0.1 | C7: -1 | D7: =B7*C7 | E7: Peso fuerte (~3.130–3.220), −22,7% a/a; reduce ingresos en COP.
A8: Petróleo / fertilizantes | B8: 0.1 | C8: 1 | D8: =B8*C8 | E8: Brent ~US$96 (+21% m/m); fertilizantes +22,5% en 2026.
A9: Político / comercial | B9: 0.1 | C9: 1 | D9: =B9*C9 | E9: Arancel 50% EE.UU. a Brasil desvía demanda hacia Colombia; EUDR aplazado.
A10: Posicionamiento especulativo | B10: 0.05 | C10: -1 | D10: =B10*C10 | E10: Liquidación de largos; sondeo Reuters: arábica ~US$3/lb a fin de año.
A11: Puntaje neto | B11: =SUM(B4:B10) | D11: =SUM(D4:D10)
A12: Modificador (acotado) = collar[paso × puntaje] | D12: =MAX(-Entradas!$B$32,MIN(Entradas!$B$32,Entradas!$B$31*D11))
A14: Sub-índice de oferta y demanda cafetera (D2 §6.1) – alimenta el puntaje del factor 1
A15: Componente | B15: Peso | C15: Puntaje (−2…+2) | D15: Contribución | E15: Lectura al corte
A16: Nivel de stocks certificados vs. rango 5 años | B16: 0.25 | C16: 2 | D16: =B16*C16 | E16: 223.911 sacos el 1-sep: mínimo desde 1999
A17: Tendencia 20 días de stocks certificados | B17: 0.15 | C17: 2 | D17: =B17*C17 | E17: 264.179 → 231.445 → 223.911: −15% en ~20 días
A18: Cola de graduación y tendencia 5 días | B18: 0.15 | C18: 1 | D18: =B18*C18 | E18: Sin cola relevante reportada
A19: Estructura de la curva (backwardation) | B19: 0.1 | C19: 1 | D19: =B19*C19 | E19: Backwardation moderada
A20: Balance global O&D (Brasil, Vietnam) | B20: 0.2 | C20: -2 | D20: =B20*C20 | E20: Superávit 8,2 M sacos 2026/27; Brasil 75–77 M
A21: Balance colombiano (producción 12 meses) | B21: 0.15 | C21: 2 | D21: =B21*C21 | E21: 12,4 M sacos, −17% a/a
A22: Sub-índice neto | D22: =SUM(D16:D21)
A23: Puntaje sugerido para el factor 1 (≥+1,5→+2; +0,5…+1,5→+1; −0,5…+0,5→0; −1,5…−0,5→−1; ≤−1,5→−2) | D23: =IF(D22>=1.5,2,IF(D22>=0.5,1,IF(D22>-0.5,0,IF(D22>-1.5,-1,-2))))
A24: Copie el valor de D23 en C4 si el comité lo ratifica (mediana de tres puntajes; pre-registro con sello de tiempo).

Sheet Calculo
A1: Cálculo del PVC (D2 §4–7)
A3: Paso | B3: Fórmula | C3: Valor
A4: L – mirada atrás ponderada 1:2:3:4:5 | B4: (Entradas!$B$6*1+Entradas!$B$7*2+Entradas!$B$8*3+Entradas!$B$9*4+Entradas!$B$10*5)/15 | C4: =(Entradas!$B$6*1+Entradas!$B$7*2+Entradas!$B$8*3+Entradas!$B$9*4+Entradas!$B$10*5)/15
A5: Impulso (acotado) | B5: MAX(-Entradas!$B$30,MIN(Entradas!$B$30,0.5*(Entradas!$B$10/Entradas!$B$6-1)*3/5)) | C5: =MAX(-Entradas!$B$30,MIN(Entradas!$B$30,0.5*(Entradas!$B$10/Entradas!$B$6-1)*3/5))
A6: P sin impulso – (C/100+Δ)×lb×k×TRM | B6: (Entradas!$B$18/100+Entradas!$B$19)*Entradas!$B$22*Entradas!$B$21*Entradas!$B$20 | C6: =(Entradas!$B$18/100+Entradas!$B$19)*Entradas!$B$22*Entradas!$B$21*Entradas!$B$20
A7: P – proyección con impulso | B7: C6*(1+C5) | C7: =C6*(1+C5)
A8: Ancla – mezcla L/P | B8: Entradas!$B$28*C4+Entradas!$B$29*C7 | C8: =Entradas!$B$28*C4+Entradas!$B$29*C7
A9: PEC 30 días – FNC 30 días + PEC-ADD | B9: Entradas!$B$11+Entradas!$B$16 | C9: =Entradas!$B$11+Entradas!$B$16
A10: Mínimo de atractivo – PEC 30 días × (1+p) | B10: C9*(1+Entradas!$B$17) | C10: =C9*(1+Entradas!$B$17)
A11: Costo escalado al corte | B11: Entradas!$B$24*(1+Entradas!$B$25) | C11: =Entradas!$B$24*(1+Entradas!$B$25)
A12: Piso – costo × (1 + margen) | B12: C11*(1+Entradas!$B$26) | C12: =C11*(1+Entradas!$B$26)
A13: Modificador (de Scorecard) | B13: Scorecard!D12 | C13: =Scorecard!D12
A14: Ancla × (1 + Modificador) | B14: C8*(1+C13) | C14: =C8*(1+C13)
A15: PVC bruto – máx(Piso ; Mínimo de atractivo ; Ancla×(1+Mod)) | B15: MAX(C12,C10,C14) | C15: =MAX(C12,C10,C14)
A16: Reajuste entre franjas – banda muerta y tope bajista | B16: IF(Entradas!$B$33=0,C15,IF(C15>=Entradas!$B$33*(1-Entradas!$B$34),MAX(C15,Entradas!$B$33),MAX(C15,Entradas!$B$33*(1-Entradas!$B$35)))) | C16: =IF(Entradas!$B$33=0,C15,IF(C15>=Entradas!$B$33*(1-Entradas!$B$34),MAX(C15,Entradas!$B$33),MAX(C15,Entradas!$B$33*(1-Entradas!$B$35))))
A17: PVC – redondeado | B17: ROUND(C16/Entradas!$B$36,0)*Entradas!$B$36 | C17: =ROUND(C16/Entradas!$B$36,0)*Entradas!$B$36
A18: Término que gobierna | B18: IF(C12>=MAX(C10,C14),"piso",IF(C10>=C14,"PEC","mercado")) | C18: =IF(C12>=MAX(C10,C14),"piso",IF(C10>=C14,"PEC","mercado"))
A19: PVC vs. PEC del día de corte (FNC + PEC-ADD) | B19: C17/(Entradas!$B$15+Entradas!$B$16)-1 | C19: =C17/(Entradas!$B$15+Entradas!$B$16)-1
A20: PVC vs. PEC 30 días | B20: C17/C9-1 | C20: =C17/C9-1
A21: PVC vs. FNC del día de corte | B21: C17/Entradas!$B$15-1 | C21: =C17/Entradas!$B$15-1
A22: PVC vs. máximo FNC 90 días (prueba §4.5; si < 0, el acta lo justifica) | B22: C17/Entradas!$B$12-1 | C22: =C17/Entradas!$B$12-1
A23: PVC vs. promedio FNC 180 días (prueba §4.5) | B23: C17/Entradas!$B$14-1 | C23: =C17/Entradas!$B$14-1
A24: PVC vs. costo escalado | B24: C17/C11-1 | C24: =C17/C11-1
A25: Retorno bruto sobre costo económico (×) | B25: C17/C11 | C25: =C17/C11
A26: Retorno bruto sobre desembolso de caja (×) | B26: C17/(Entradas!$B$27*C11) | C26: =C17/(Entradas!$B$27*C11)
A27: PVC por kilo | B27: C17/125 | C27: =C17/125
A28: PVC por arroba | B28: C17/10 | C28: =C17/10
A29: PVC en US$ por carga | B29: C17/Entradas!$B$20 | C29: =C17/Entradas!$B$20
A30: PVC en US$/lb excelso equivalente | B30: C17/Entradas!$B$20/Entradas!$B$22 | C30: =C17/Entradas!$B$20/Entradas!$B$22
A31: PVC en US$/lb pergamino | B31: C17/Entradas!$B$20/Entradas!$B$23 | C31: =C17/Entradas!$B$20/Entradas!$B$23
A32: Umbral del disparador (FNC ≥ PVC en 10 de 15 publicaciones) | B32: C17 | C32: =C17
A33: Cifra de salida por carga (productor y tostador) | B33: C17*Entradas!$B$42 | C33: =C17*Entradas!$B$42
A34: PVC vs. máximo FNC 30 días (prueba §4.5) | B34: C17/Entradas!$B$13-1 | C34: =C17/Entradas!$B$13-1

Sheet Escalera
A1: Escalera de calidad CTCx (D2 §8) · columnas FCA/CIP desde la hoja Pila_de_precios (D2 §13.1)
A3: Banda | B3: Mult. | C3: COP/carga | D3: COP/kg | E3: US$/carga | F3: US$/lb excelso | G3: US$/lb perg. | H3: FCA Bogotá (≈FOB) US$/lb | I3: Referencia FOB (SCTG) | J3: Sobreprecio FCA | K3: CIP aeropuerto al MOQ (aéreo) US$/lb | L3: Sobreprecio destino
A4: Referencia ×1,0 (< 80; no se compra) | B4: =1 | C4: =Calculo!$C$17*B4 | D4: =C4/125 | E4: =C4/Entradas!$B$20 | F4: =C4/Entradas!$B$20/Entradas!$B$22 | G4: =C4/Entradas!$B$20/Entradas!$B$23 | H4: no se vende | I4: =Entradas!$B$46 | J4: —
A5: Black 80,0–83,9 | B5: =Entradas!$B$37 | C5: =Calculo!$C$17*B5 | D5: =C5/125 | E5: =C5/Entradas!$B$20 | F5: =C5/Entradas!$B$20/Entradas!$B$22 | G5: =C5/Entradas!$B$20/Entradas!$B$23 | H5: =Pila_de_precios!B65 | I5: =Entradas!$B$47 | J5: =H5/I5-1 | K5: =Pila_de_precios!B66 | L5: =K5/(I5+Entradas!$B$45)-1
A6: Red 84,0–85,9 | B6: =Entradas!$B$38 | C6: =Calculo!$C$17*B6 | D6: =C6/125 | E6: =C6/Entradas!$B$20 | F6: =C6/Entradas!$B$20/Entradas!$B$22 | G6: =C6/Entradas!$B$20/Entradas!$B$23 | H6: =Pila_de_precios!C65 | I6: =Entradas!$B$48 | J6: =H6/I6-1 | K6: =Pila_de_precios!C66 | L6: =K6/(I6+Entradas!$B$45)-1
A7: Blue 86,0–87,9 | B7: =Entradas!$B$39 | C7: =Calculo!$C$17*B7 | D7: =C7/125 | E7: =C7/Entradas!$B$20 | F7: =C7/Entradas!$B$20/Entradas!$B$22 | G7: =C7/Entradas!$B$20/Entradas!$B$23 | H7: =Pila_de_precios!D65 | I7: =Entradas!$B$49 | J7: =H7/I7-1 | K7: =Pila_de_precios!D66 | L7: =K7/(I7+Entradas!$B$45)-1
A8: Gold 88,0–88,9 | B8: =Entradas!$B$40 | C8: =Calculo!$C$17*B8 | D8: =C8/125 | E8: =C8/Entradas!$B$20 | F8: =C8/Entradas!$B$20/Entradas!$B$22 | G8: =C8/Entradas!$B$20/Entradas!$B$23 | H8: =Pila_de_precios!E65 | I8: =Entradas!$B$50 | J8: =H8/I8-1 | K8: =Pila_de_precios!E66 | L8: =K8/(I8+Entradas!$B$45)-1
A9: Tyrian ≥ 89,0 (genética A/B) – subasta desde el precio Gold (Grado_y_Tyrian)
A11: Ajuste por factor de rendimiento: PVC_FR = PVC × FNC_FR / FNC_FR94 (tabla FNC del día de recibo). Ejemplo con la tabla del 4-sep-2026:
A12: FR | B12: FNC 4-sep-2026 | C12: Coeficiente | D12: PVC ×1,0 ajustado | E12: Black | F12: Red | G12: Blue | H12: Gold
A13: 88 | B13: 2155875 | C13: =B13/$B$16 | D13: =Calculo!$C$17*C13 | E13: =D13*Entradas!$B$37 | F13: =D13*Entradas!$B$38 | G13: =D13*Entradas!$B$39 | H13: =D13*Entradas!$B$40
A14: 90 | B14: 2136625 | C14: =B14/$B$16 | D14: =Calculo!$C$17*C14 | E14: =D14*Entradas!$B$37 | F14: =D14*Entradas!$B$38 | G14: =D14*Entradas!$B$39 | H14: =D14*Entradas!$B$40
A15: 92 | B15: 2106375 | C15: =B15/$B$16 | D15: =Calculo!$C$17*C15 | E15: =D15*Entradas!$B$37 | F15: =D15*Entradas!$B$38 | G15: =D15*Entradas!$B$39 | H15: =D15*Entradas!$B$40
A16: 94 | B16: 2080000 | C16: =B16/$B$16 | D16: =Calculo!$C$17*C16 | E16: =D16*Entradas!$B$37 | F16: =D16*Entradas!$B$38 | G16: =D16*Entradas!$B$39 | H16: =D16*Entradas!$B$40
A17: 96 | B17: 2052625 | C17: =B17/$B$16 | D17: =Calculo!$C$17*C17 | E17: =D17*Entradas!$B$37 | F17: =D17*Entradas!$B$38 | G17: =D17*Entradas!$B$39 | H17: =D17*Entradas!$B$40
A18: 98 | B18: 2029250 | C18: =B18/$B$16 | D18: =Calculo!$C$17*C18 | E18: =D18*Entradas!$B$37 | F18: =D18*Entradas!$B$38 | G18: =D18*Entradas!$B$39 | H18: =D18*Entradas!$B$40
A19: 100 | B19: 2006625 | C19: =B19/$B$16 | D19: =Calculo!$C$17*C19 | E19: =D19*Entradas!$B$37 | F19: =D19*Entradas!$B$38 | G19: =D19*Entradas!$B$39 | H19: =D19*Entradas!$B$40

Sheet Contrato
A1: Oferta comercial y contrato de franja para un lote (D2 §11)
A3: Campo | B3: Valor | C3: Regla
A4: Banda del lote (Black / Red / Blue / Gold) | B4: Black | C4: Del resultado de la muestra (Formato 1)
A5: FR de la muestra | B5: 94 | C5: Ajuste por tabla FNC del día de cada entrega
A6: Cargas declaradas por el productor (N) | B6: 5 | C6: =IF(B6<IF(OR(B4="Black",B4="Red"),5,3),"POR DEBAJO DEL MÍNIMO","mínimo cumplido: "&IF(OR(B4="Black",B4="Red"),5,3)&" cargas")
A7: Máximo N ofrecido por CTCx | B7: 10 | C7: Según demanda esperada de la banda (D2 §13.2)
A8: Franjas de antigüedad de la catación (0 = oferta inicial) | B8: 0 | C8: Reemisión automática: −5% por franja; máx. 2 en Black/Red, 1 en Blue/Gold
A10: Multiplicador de la banda | B10: =IF(B4="Black",Entradas!$B$37,IF(B4="Red",Entradas!$B$38,IF(B4="Blue",Entradas!$B$39,Entradas!$B$40)))
A11: Coeficiente FR | B11: =IFERROR(VLOOKUP(B5,Escalera!$A$13:$C$19,3,FALSE),1)
A12: Precio del contrato por carga = PVC × coef. FR × mult. × (1 − antigüedad) | B12: =Calculo!$C$17*B11*B10*(1-B8*Entradas!$B$43)
A13: Carga 1: compra inmediata de CTCx (valor) | B13: =B12 | C13: Entrega, verificación y pago a 2 días hábiles (D2 §11.3)
A14: Cantidad reservada (N − 1) | B14: =MIN(B6,B7)-1 | C14: Reservada al precio del contrato hasta el cierre de la franja; se llama contra ventas
A15: Valor de la reserva al precio del contrato | B15: =B14*B12
A16: Retiro libre por corte mensual (cargas) | B16: =B14*Entradas!$B$41 | C16: 25% de la cantidad reservada vigente, por escrito, sin costo
A17: Cifra de salida por carga retirada por encima del retiro libre | B17: =Calculo!$C$17*Entradas!$B$42 | C17: 7,5% del PVC × 1,0; también la paga el tostador que cancela una reserva a fórmula
A18: Exposición firme de CTCx por este lote (carga 1) | B18: =B13 | C18: Única compra en firme; la reserva no es exposición (D2 §13.2)
A20: Contribución de catación pagada por el productor (por adelantado) | B20: =Entradas!$B$51*(1-Entradas!$B$52) | C20: Subsidio por defecto 30%; 50/60/70% sólo por criterios publicados (D2 §11.4)
A21: Contribución como % del valor de la carga 1 | B21: =B20/B13
A23: Lado tostador: anticipo al comprar en la plataforma | B23: =Entradas!$B$44 | C23: Resto a la confirmación de compra de CTCx al productor; sin cancelación
A24: Precio CIP aeropuerto de esta banda al MOQ (US$/lb, aéreo; Pila_de_precios) | B24: =IF(B4="Black",Escalera!K5,IF(B4="Red",Escalera!K6,IF(B4="Blue",Escalera!K7,Escalera!K8))) | C24: Precio en US$ a la TRM del corte, fijo en la ventana; flete y seguro como líneas separadas

Sheet Disparador
A1: Vigilancia diaria del disparador de corrección al alza (D2 §7.5)
A2: Registre las últimas 15 publicaciones diarias del precio interno FNC FR 94. El disparador se activa si en ≥ 10 de ellas FNC ≥ PVC vigente. Magnitud: (promedio de las 15 + PEC-ADD) × (1 + p).
A3: Día | B3: FNC FR 94 | C3: ¿≥ PVC?
A4: 1 | B4: 2080000 | C4: =IF(B4>=$B$21,1,0)
A5: 2 | B5: 2080000 | C5: =IF(B5>=$B$21,1,0)
A6: 3 | B6: 2080000 | C6: =IF(B6>=$B$21,1,0)
A7: 4 | B7: 2080000 | C7: =IF(B7>=$B$21,1,0)
A8: 5 | B8: 2080000 | C8: =IF(B8>=$B$21,1,0)
A9: 6 | B9: 2080000 | C9: =IF(B9>=$B$21,1,0)
A10: 7 | B10: 2080000 | C10: =IF(B10>=$B$21,1,0)
A11: 8 | B11: 2080000 | C11: =IF(B11>=$B$21,1,0)
A12: 9 | B12: 2080000 | C12: =IF(B12>=$B$21,1,0)
A13: 10 | B13: 2080000 | C13: =IF(B13>=$B$21,1,0)
A14: 11 | B14: 2080000 | C14: =IF(B14>=$B$21,1,0)
A15: 12 | B15: 2080000 | C15: =IF(B15>=$B$21,1,0)
... A18: 15 | B18: 2080000 | C18: =IF(B18>=$B$21,1,0)
A20: PVC vigente | B20: =Calculo!$C$17
A21: Umbral | B21: =B20
A22: Días ≥ PVC | B22: =SUM(C4:C18)
A23: ¿Disparador activado? | B23: =IF(B22>=10,"SÍ: recalcular y publicar acta; rige desde el corte de fin de mes","no")
A24: Promedio FNC 15 días | B24: =AVERAGE(B4:B18)
A25: PVC corregido = máx(PVC ; (promedio + PEC-ADD) × (1+p)), redondeado | B25: =MAX(B20,ROUND((B24+Entradas!$B$16)*(1+Entradas!$B$17)/Entradas!$B$36,0)*Entradas!$B$36)
A26: Semáforo semanal | B26: =IF(B18>=B20,"ROJO",IF(B18>=B20*0.92,"AMARILLO","VERDE")) | D26: Verde: FNC ≤ PVC − 8%; amarillo: entre PVC − 8% y PVC; rojo: FNC ≥ PVC

Sheet Calendario
A1: Calendario · franjas de venta 2027 (D2 §7.2)
A3: Franja | B3: Corte de datos | C3: Publicación | D3: Muestras | E3: Declaración inicial y carga 1 | F3: Embarque aéreo | G3: Ventana Cherry Picked | H3: Mirada atrás | I3: Proyección
A4: F1-2027 | B4: 30-sep-2026 | C4: 15-oct-2026 | D4: 15-oct → 15-nov-2026 | E4: 15-nov → 1-dic-2026 | F4: 15-dic-2026 | G4: 15-dic-2026 → 15-mar-2027 | H4: may – sep 2026 | I4: dic 2026 – feb 2027
A5: F2-2027 | B5: 31-dic-2026 | C5: 15-ene-2027 | D5: 15-ene → 15-feb-2027 | E5: 15-feb → 1-mar-2027 | F5: 15-mar-2027 | G5: 15-mar → 15-jun-2027 | H5: ago – dic 2026 | I5: mar – may 2027
A6: F3-2027 | B6: 31-mar-2027 | C6: 15-abr-2027 | D6: 15-abr → 15-may-2027 | E6: 15-may → 1-jun-2027 | F6: 15-jun-2027 | G6: 15-jun → 15-sep-2027 | H6: nov 2026 – mar 2027 | I6: jun – ago 2027
A7: F4-2027 | B7: 30-jun-2027 | C7: 15-jul-2027 | D7: 15-jul → 15-ago-2027 | E7: 15-ago → 1-sep-2027 | F7: 15-sep-2027 | G7: 15-sep → 15-dic-2027 | H7: feb – jun 2027 | I7: sep – nov 2027
A9: Edición de transición F4-2026: publicada el 7-sep-2026 (v1.5.2) y reeditada en v2.0 el 8-sep-2026 con el mismo número; ofertas rodantes hasta el 15-oct-2026 (publicación de F1-2027); embarque con las cargas 1 de F1-2027 el 15-dic-2026.

Sheet Datos_mensual
A1: Serie mensual: oficial FNC (v2.1) y reconstrucción retirada (D1 §4, Anexos A y B)
A3: Año | B3: Mes | C3: C (US¢/lb) | D3: TRM | E3: Precio reconstruido (COP/carga) | F3: Fuente | G3: Precio oficial FNC (COP/carga) | H3: Año | I3: Δ efectivo | J3: Error reconstr.
A4: 2018 | B4: 5 | C4: 118 | D4: 2880 | E4: =(C4/100+VLOOKUP(A4,$H$4:$I$12,2,FALSE))*205.2*0.967*D4 | F4: reconstruido (D1 Anexo B) | G4: 754209.68 | H4: 2018 | I4: 0.2 | J4: =E4/G4-1
A5: 2018 | B5: 6 | C5: 116 | D5: 2930 | E5: =(C5/100+VLOOKUP(A5,$H$4:$I$12,2,FALSE))*205.2*0.967*D5 | F5: reconstruido (D1 Anexo B) | G5: 746400 | H5: 2019 | I5: 0.2 | J5: =E5/G5-1
A6: 2018 | B6: 7 | C6: 111 | D6: 2900 | E6: =(C6/100+VLOOKUP(A6,$H$4:$I$12,2,FALSE))*205.2*0.967*D6 | F6: reconstruido (D1 Anexo B) | G6: 717838.71 | H6: 2020 | I6: 0.3 | J6: =E6/G6-1
A7: 2018 | B7: 8 | C7: 103 | D7: 2960 | E7: =(C7/100+VLOOKUP(A7,$H$4:$I$12,2,FALSE))*205.2*0.967*D7 | F7: reconstruido (D1 Anexo B) | G7: 705064.52 | H7: 2021 | I7: 0.35 | J7: =E7/G7-1
A8: 2018 | B8: 9 | C8: 100 | D8: 3030 | E8: =(C8/100+VLOOKUP(A8,$H$4:$I$12,2,FALSE))*205.2*0.967*D8 | F8: reconstruido (D1 Anexo B) | G8: 686933.33 | H8: 2022 | I8: 0.3 | J8: =E8/G8-1
A9: 2018 | B9: 10 | C9: 115 | D9: 3080 | E9: =(C9/100+VLOOKUP(A9,$H$4:$I$12,2,FALSE))*205.2*0.967*D9 | F9: reconstruido (D1 Anexo B) | G9: 796774.19 | H9: 2023 | I9: 0.25 | J9: =E9/G9-1
A10: 2018 | B10: 11 | C10: 113 | D10: 3200 | E10: =(C10/100+VLOOKUP(A10,$H$4:$I$12,2,FALSE))*205.2*0.967*D10 | F10: reconstruido (D1 Anexo B) | G10: 804283.33 | H10: 2024 | I10: 0.15 | J10: =E10/G10-1
A11: 2018 | B11: 12 | C11: 103 | D11: 3220 | E11: =(C11/100+VLOOKUP(A11,$H$4:$I$12,2,FALSE))*205.2*0.967*D11 | F11: reconstruido (D1 Anexo B) | G11: 727645.16 | H11: 2025 | I11: 0 | J11: =E11/G11-1
A12: 2019 | B12: 1 | C12: 104 | D12: 3160 | E12: =(C12/100+VLOOKUP(A12,$H$4:$I$12,2,FALSE))*205.2*0.967*D12 | F12: reconstruido (D1 Anexo B) | G12: 727274.19 | H12: 2026 | I12: 0.3 | J12: =E12/G12-1
A13: 2019 | B13: 2 | C13: 102 | D13: 3120 | E13: =(C13/100+VLOOKUP(A13,$H$4:$I$12,2,FALSE))*205.2*0.967*D13 | F13: reconstruido (D1 Anexo B) | G13: 708089.29 | J13: =E13/G13-1
A14: 2019 | B14: 3 | C14: 97 | D14: 3140 | E14: =(C14/100+VLOOKUP(A14,$H$4:$I$12,2,FALSE))*205.2*0.967*D14 | F14: reconstruido (D1 Anexo B) | G14: 690580.65 | J14: =E14/G14-1
A15: 2019 | B15: 4 | C15: 94 | D15: 3180 | E15: =(C15/100+VLOOKUP(A15,$H$4:$I$12,2,FALSE))*205.2*0.967*D15 | F15: reconstruido (D1 Anexo B) | G15: 680566.67 | J15: =E15/G15-1
A16: 2019 | B16: 5 | C16: 93 | D16: 3300 | E16: =(C16/100+VLOOKUP(A16,$H$4:$I$12,2,FALSE))*205.2*0.967*D16 | F16: reconstruido (D1 Anexo B) | G16: 724064.52 | J16: =E16/G16-1
A17: 2019 | B17: 6 | C17: 101 | D17: 3250 | E17: =(C17/100+VLOOKUP(A17,$H$4:$I$12,2,FALSE))*205.2*0.967*D17 | F17: reconstruido (D1 Anexo B) | G17: 779916.67 | J17: =E17/G17-1
A18: 2019 | B18: 7 | C18: 105 | D18: 3210 | E18: =(C18/100+VLOOKUP(A18,$H$4:$I$12,2,FALSE))*205.2*0.967*D18 | F18: reconstruido (D1 Anexo B) | G18: 796483.87 | J18: =E18/G18-1
A19: 2019 | B19: 8 | C19: 98 | D19: 3400 | E19: =(C19/100+VLOOKUP(A19,$H$4:$I$12,2,FALSE))*205.2*0.967*D19 | F19: reconstruido (D1 Anexo B) | G19: 798935.48 | J19: =E19/G19-1
A20: 2019 | B20: 9 | C20: 100 | D20: 3410 | E20: =(C20/100+VLOOKUP(A20,$H$4:$I$12,2,FALSE))*205.2*0.967*D20 | F20: reconstruido (D1 Anexo B) | G20: 815450 | J20: =E20/G20-1
A21: 2019 | B21: 10 | C21: 98 | D21: 3430 | E21: =(C21/100+VLOOKUP(A21,$H$4:$I$12,2,FALSE))*205.2*0.967*D21 | F21: reconstruido (D1 Anexo B) | G21: 819580.65 | J21: =E21/G21-1
A22: 2019 | B22: 11 | C22: 110 | D22: 3410 | E22: =(C22/100+VLOOKUP(A22,$H$4:$I$12,2,FALSE))*205.2*0.967*D22 | F22: reconstruido (D1 Anexo B) | G22: 909600 | J22: =E22/G22-1
A23: 2019 | B23: 12 | C23: 127 | D23: 3380 | E23: =(C23/100+VLOOKUP(A23,$H$4:$I$12,2,FALSE))*205.2*0.967*D23 | F23: reconstruido (D1 Anexo B) | G23: 999129.03 | J23: =E23/G23-1
A24: 2020 | B24: 1 | C24: 114 | D24: 3300 | E24: =(C24/100+VLOOKUP(A24,$H$4:$I$12,2,FALSE))*205.2*0.967*D24 | F24: reconstruido (D1 Anexo B) | G24: 886161.29 | J24: =E24/G24-1
... A103: 2026 | B103: 8 | C103: 330 | D103: 3130 | E103: =(C103/100+VLOOKUP(A103,$H$4:$I$12,2,FALSE))*205.2*0.967*D103 | F103: reconstruido (D1 Anexo B) | G103: 2263548.4 | J103: =E103/G103-1
A105: Costo medio anual usado en el piso (COP/carga, aprox.):
A106: 2019 | B106: 700000
A107: 2020 | B107: 745000
A108: 2021 | B108: 860000
A109: 2022 | B109: 1120000
A110: 2023 | B110: 1280000
A111: 2024 | B111: 1350000
A112: 2025 | B112: 1447000
A113: 2026 | B113: 1550800

Sheet BackProof
A1: Back-proof 2019–2026 · serie oficial FNC · calendario v2.0 con disparador (D2 §9) – valores del motor pvc_model_v2.py
A3: Franja | B3: Mirada atrás | C3: L | D3: Ancla | E3: PEC × 1,08 | F3: Piso | G3: Gobierna | H3: PVC | I3: PVC tras disparo | J3: Realizado | K3: Prima ×1,0 | L3: Black vs coop | M3: Disparos | N3: Cobertura
A4: 2019F1 | B4: 2018-05..2018-09 | C4: 710363.37 | D4: 693638.33 | E4: 761918.98 | F4: 1050000 | G4: piso | H4: 1050000 | I4: 1050000 | J4: 721002.88 | K4: 0.45654066 | L4: 0.58469419 | M4: 0 | N4: 1
A5: 2019F2 | B5: 2018-08..2018-12 | C5: 754974.19 | D5: 746839.04 | E5: 807074.91 | F5: 1050000 | G5: piso | H5: 1050000 | I5: 1050000 | J5: 698403.94 | K5: 0.50447954 | L5: 0.63685096 | M5: 0 | N5: 1
A6: 2019F3 | B6: 2018-11..2019-03 | C6: 715110.44 | D6: 693583.12 | E6: 765964.43 | F6: 1050000 | G6: piso | H6: 1050000 | I6: 1050000 | J6: 791778.67 | K6: 0.3262802 | L6: 0.44297278 | M6: 0 | N6: 1
A7: 2019F4 | B7: 2019-02..2019-06 | C7: 728452.8 | D7: 758531.96 | E7: 865052.37 | F7: 1050000 | G7: piso | H7: 1050000 | I7: 1050000 | J7: 848210.22 | K7: 0.24104305 | L7: 0.35023605 | M7: 0 | N7: 1
A8: 2020F1 | B8: 2019-05..2019-09 | C8: 796422.76 | D8: 816383.99 | E8: 904464.52 | F8: 1050000 | G8: piso | H8: 1050000 | I8: 1050000 | J8: 931464.59 | K8: 0.13026175 | L8: 0.22970768 | M8: 0 | N8: 1
A9: 2020F2 | B9: 2019-08..2019-12 | C9: 901508.17 | D9: 960539.1 | E9: 1108194 | F9: 1117500 | G9: piso | H9: 1120000 | I9: 1270000 | J9: 1129210.4 | K9: 0.082737093 | L9: 0.17800157 | M9: 1 | N9: 0.66666667
A10: 2020F3 | B10: 2019-11..2020-03 | C10: 994581.56 | D10: 1076890.2 | E10: 1267984.6 | F10: 1117500 | G10: PEC | H10: 1270000 | I10: 1270000 | J10: 1036073.1 | K10: 0.23246656 | L10: 0.34090496 | M10: 0 | N10: 1
A11: 2020F4 | B11: 2020-02..2020-06 | C11: 1054111.6 | D11: 1024411.2 | E11: 1067899.2 | F11: 1117500 | G11: piso | H11: 1120000 | I11: 1270000 | J11: 1079805.7 | K11: 0.13428818 | L11: 0.23408837 | M11: 1 | N11: 0.66666667
A12: 2021F1 | B12: 2020-05..2020-09 | C12: 1085724.2 | D12: 1117735.6 | E12: 1266919.5 | F12: 1117500 | G12: PEC | H12: 1270000 | I12: 1270000 | J12: 1078135.6 | K12: 0.17870012 | L12: 0.28240789 | M12: 0 | N12: 1
A13: 2021F2 | B13: 2020-08..2020-12 | C13: 1066871.5 | D13: 1048611.7 | E13: 1162041.9 | F13: 1290000 | G13: piso | H13: 1290000 | I13: 1290000 | J13: 1249800.4 | K13: 0.038349014 | L13: 0.12970801 | M13: 1 | N13: 0.66666667
A14: 2021F3 | B14: 2020-11..2021-03 | C14: 1106262.6 | D14: 1140954.1 | E14: 1282224.7 | F14: 1290000 | G14: piso | H14: 1290000 | I14: 1580000 | J14: 1562782.8 | K14: -0.051408645 | L14: 0.032053035 | M14: 2 | N14: 0.33333333
A15: 2021F4 | B15: 2021-02..2021-06 | C15: 1313042.8 | D15: 1384561.7 | E15: 1575894.5 | F15: 1290000 | G15: PEC | H15: 1580000 | I15: 1900000 | J15: 1832242.9 | K15: -0.020849708 | L15: 0.065300696 | M15: 2 | N15: 0.33333333
... A34: 2026F3 | B34: 2025-11..2026-03 | C34: 2406400.8 | D34: 2290149.5 | E34: 2470242.4 | F34: 2326200 | G34: PEC · tope 15% | H34: 2580000 | I34: 2580000 | J34: 2198418 | K34: 0.17513649 | L34: 0.27853072 | M34: 0 | N34: 1
A36: Resumen
A37: Prima media ×1,0 | C37: 0.19322078
A38: Mediana | C38: 0.1559825
A39: Peor franja | C39: -0.051408645
A40: Franjas negativas | C40: 4
A41: Black vs coop, media | C41: 0.29820614
A42: Black, peor | C42: 0.032053035
A43: Franjas con disparo | C43: 9
A44: Gobierna piso | C44: 14
A45: Gobierna PEC | C45: 17
A46: Cobertura media | C46: 0.86021505

Sheet Grado_y_Tyrian
A1: Matriz de grado (D2 §8.1) y subasta Tyrian (D2 §8.2)
A3: Campo | B3: Valor | C3: Regla
A4: Puntaje SCA de la muestra | B4: 86.7 | C4: Catador Q, formato SCA
A5: Reconocimientos (–, +, ++) | B5: – | C5: + = 1 punto (lista publicada); ++ = 2 puntos (extraordinario)
A6: Genética (A, B, C) | B6: B | C6: Lista A/B/C del comité para la franja
A7: Factor de rendimiento | B7: 92 | C7: ≤ 94 (Black hasta 98); el FR excluye, no baja de banda
A9: Puntaje de grado | B9: =B4+IF(B5="+",1,IF(B5="++",2,0))
A10: Banda por puntaje | B10: =IF(B9>=89.0,"Tyrian",IF(B9>=88,"Gold",IF(B9>=86,"Blue",IF(B9>=84,"Red",IF(B9>=80,"Black","no entra")))))
A11: Tope por genética | B11: =IF(B6="C",IF(OR(B10="Gold",B10="Tyrian"),"Blue",B10),B10) | C11: C alcanza como máximo Blue; Gold y Tyrian sólo A/B
A12: Regla genética A bajo 86 | B12: =IF(AND(B6="A",B9<86),"segunda catación interna (costo CTCx); si se confirma, se declina con retroalimentación","ok")
A13: Puerta de FR | B13: =IF(B11="no entra","no entra",IF(B7>IF(B11="Black",98,94),"FR fuera de rango: no entra","ok"))
A14: GRADO | B14: =IF(B12<>"ok",B12,IF(B13<>"ok",B13,B11))
A15: Precio del contrato por carga FR 94 | B15: =IF(B14="Black",Escalera!C5,IF(B14="Red",Escalera!C6,IF(B14="Blue",Escalera!C7,IF(B14="Gold",Escalera!C8,IF(B14="Tyrian",Escalera!C8,0))))) | C15: Tyrian: precio de partida de la subasta = Gold
A17: Subasta Tyrian
A18: Precio de partida (= Gold) | B18: =Escalera!C8
A19: Precio de cierre de la subasta por carga | B19: =Calculo!$C$17*2.6 | C19: Ejemplo: PVC × 2,6; reserva = partida
A20: Excedente sobre la partida | B20: =MAX(0,B19-B18)
A21: Productor (80% del excedente) | B21: =B20*0.8
A22: CTCx (19% del excedente) | B22: =B20*(1-0.8)
A23: Precio total al productor por carga | B23: =B18+B21 | C23: Carga 1 comprada a Gold y reliquidada al alza; liquidación a ≤ 2 días hábiles del cierre
A25: MOQ del comprador en verde empacado al vacío (kg)
A26: Black | B26: 228 | C26: Bolsas de 6 kg (también 3 y 12 kg); todo MOQ es múltiplo de 6; desde el productor la unidad es la carga de pergamino (kg garantizados por carga: Pila_de_precios)
A27: Red | B27: 228
A28: Blue | B28: 150
A29: Gold | B29: 60
A30: Tyrian | B30: 30

Sheet Pila_de_precios
A1: Pila de precios al comprador (D2 §13.1) · US$/kg de verde garantizado a la TRM del corte · N0 finca → N1 empacado → N2 FCA Bogotá (≈FOB) → N3 CIP aeropuerto (≈CIF) → N4 DDP
A2: Fondo NARANJA = costo ESTIMADO (valor de relleno; sustituir por la cotización sin tocar nada más). Fondo AMARILLO = decisión CTCx. Azul = entrada. Los Incoterms aéreos son los del contrato; FOB/CIF sólo como analogía.
A3: Parámetro | B3: Valor | C3: Unidad | D3: Naturaleza / nota
A4: Kilos de excelso por carga FR 94 | B4: 93.09 | C4: kg | D4: Medido · Tabla FNC (93,09 kg); FR 96 = 91,15 kg
A5: Kilos de verde perfecto GARANTIZADOS por carga | B5: 78 | C5: kg | D5: Decisión CTCx · Propuesta: 13 bolsas de 6 kg; admite 16% de merma con FR 94 y 14% con FR 96. El resto va a kits, promoción y tostado
A6: Bolsa (denominador de todo MOQ) | B6: 6 | C6: kg | D6: Decisión CTCx · También 3 y 12 kg
A7: Valor recuperado del café fuera de garantía | B7: 0 | C7: US$/kg | D7: ESTIMADO (pendiente cotización) · 0 = conservador; si los kits se venden, aquí entra su valor y baja N0
A8: Procesamiento y empaque (trilla, selección, vacío 6 kg) | B8: 0.95 | C8: US$/kg | D8: ESTIMADO (pendiente cotización) · Cotizar trilladora
A9: Paletizaje en Bogotá | B9: 0.1 | C9: US$/kg | D9: ESTIMADO (pendiente cotización)
A10: Transporte interno (trilladora → Bogotá → El Dorado) | B10: 0.2 | C10: US$/kg | D10: ESTIMADO (pendiente cotización)
A11: Gastos de exportación (aduana, DEX, ICA/FNC, terminal) | B11: 0.25 | C11: US$/kg | D11: ESTIMADO (pendiente cotización)
A12: Tarifa CTCx base (cobertura + profit máximo) | B12: 1.2 | C12: US$/kg | D12: ESTIMADO (pendiente cotización) · No depende del modo de envío; se multiplica por el factor de banda
A13: Factor de banda Tarifa CTCx · Black | B13: 1 | C13: × | D13: Decisión CTCx
A14: Factor de banda Tarifa CTCx · Red | B14: 1.1 | C14: × | D14: Decisión CTCx
A15: Factor de banda Tarifa CTCx · Blue | B15: 1.25 | C15: × | D15: Decisión CTCx
... A24: Libras por kilogramo | B24: 2.20462 | C24: lb/kg | D24: Medido
A25: DDP incluye IVA (1 = sí, 0 = no) | B25: 0 | D25: Decisión CTCx · Pendiente; práctica habitual en café verde: IVA a cargo del importador
A26: Cierre de subasta Tyrian de ejemplo (× PVC) | B26: 2.6 | C26: × | D26: Entrada · Sólo para la columna Tyrian
A27: Destino DDP seleccionado (de la tabla de abajo) | B27: Estados Unidos (Miami / Nueva York) | D27: Entrada · Escribir exactamente como en la tabla de destinos
A29: Escalas de flete aéreo Bogotá → aeropuerto destino (todo incluido) · ESTIMADAS · regla: se cobra la escala del peso del pedido, nunca peor; crédito si la consolidación alcanza una escala mejor
A30: Escala desde (kg) | B30: US$/kg | C30: Hasta (kg) | D30: Nota
A31: 0 | B31: 6.5 | C31: 44
A32: 45 | B32: 5.2 | C32: 99
A33: 100 | B33: 4.2 | C33: 299
A34: 300 | B34: 3.6 | C34: 499
A35: 500 | B35: 3.2 | C35: 999
A36: 1000 | B36: 2.9 | C36: ∞
A38: Destinos DDP habilitados · costos ESTIMADOS por kg · arancel del café verde 0% en EE.UU. y UE
A39: Destino | B39: Nacionalización US$/kg | C39: Entrega final US$/kg | D39: IVA | E39: Habilitado
A40: Estados Unidos (Miami / Nueva York) | B40: 0.25 | C40: 0.4 | D40: 0 | E40: sí
A41: Países Bajos (Ámsterdam) | B41: 0.3 | C41: 0.45 | D41: 0.09 | E41: sí
A42: Alemania (Fráncfort) | B42: 0.3 | C42: 0.45 | D42: 0.07 | E42: sí
A45: Pila por banda (US$/kg de verde garantizado; CIP al MOQ de cada banda; DDP para el destino seleccionado)
A46: Concepto | B46: Black | C46: Red | D46: Blue | E46: Gold | F46: Tyrian | G46: Regla
A47: COP por carga (precio del contrato; Tyrian = cierre de ejemplo) | B47: =Escalera!C5 | C47: =Escalera!C6 | D47: =Escalera!C7 | E47: =Escalera!C8 | F47: =Calculo!$C$17*$B$26 | G47: Escalera (PVC × multiplicador)
A48: US$ por carga a la TRM del corte | B48: =B47/Entradas!$B$20 | C48: =C47/Entradas!$B$20 | D48: =D47/Entradas!$B$20 | E48: =E47/Entradas!$B$20 | F48: =F47/Entradas!$B$20 | G48: Fijo durante la ventana de venta
A49: N0 · Finca (÷ kg garantizados − crédito por café fuera de garantía) | B49: =B48/$B$5-($B$4-$B$5)*$B$7/$B$5 | C49: =C48/$B$5-($B$4-$B$5)*$B$7/$B$5 | D49: =D48/$B$5-($B$4-$B$5)*$B$7/$B$5 | E49: =E48/$B$5-($B$4-$B$5)*$B$7/$B$5 | F49: =F48/$B$5-($B$4-$B$5)*$B$7/$B$5 | G49: Sobre los kg garantizados, no sobre los 93 kg teóricos
A50: N1 · Empacado | B50: =B49+$B$8 | C50: =C49+$B$8 | D50: =D49+$B$8 | E50: =E49+$B$8 | F50: =F49+$B$8 | G50: + procesamiento y empaque
A51: FCA antes de la Tarifa CTCx | B51: =B50+$B$9+$B$10+$B$11 | C51: =C50+$B$9+$B$10+$B$11 | D51: =D50+$B$9+$B$10+$B$11 | E51: =E50+$B$9+$B$10+$B$11 | F51: =F50+$B$9+$B$10+$B$11 | G51: + paletizaje + transporte interno + exportación
A52: Tarifa CTCx en FCA (base × factor de banda + recargo FCA) | B52: =$B$12*$B$13+$B$18 | C52: =$B$12*$B$14+$B$18 | D52: =$B$12*$B$15+$B$18 | E52: =$B$12*$B$16+$B$18 | F52: =$B$12*$B$17+$B$18 | G52: No depende del modo de envío
...
